19/09/2019 07:35:44 PM Python Script is: morePVs.py
19/09/2019 07:35:44 PM study_name = test_en_mk2
19/09/2019 07:35:45 PM saved to C:\Users\z5044992\Documents\python\morePVs\DATA_EN_6\studies\tests\outputs\test_en_mk2\saved_tariffs\static_import_tariffs.csv
19/09/2019 07:35:45 PM saved to C:\Users\z5044992\Documents\python\morePVs\DATA_EN_6\studies\tests\outputs\test_en_mk2\saved_tariffs\static_solar_import_tariffs.csv
19/09/2019 07:35:45 PM saved to C:\Users\z5044992\Documents\python\morePVs\DATA_EN_6\studies\tests\outputs\test_en_mk2\saved_tariffs\static_export_tariffs.csv
19/09/2019 07:35:45 PM Running Scenario number 0 
19/09/2019 07:35:50 PM saved to C:\Users\z5044992\Documents\python\morePVs\DATA_EN_6\studies\tests\outputs\test_en_mk2\scenarios\test_en_mk2_000.csv
19/09/2019 07:35:51 PM Completed Scenario 0
19/09/2019 07:35:51 PM Running Scenario number 1 
19/09/2019 07:35:51 PM battery-id nan is not in battery_lookup.csv :
19/09/2019 07:35:51 PM 


 Exception !!!!!!
Traceback (most recent call last):
  File "C:/Users/z5044992/Documents/python/morePVs/morePVs.py", line 2631, in main
    runScenario(s)
  File "C:/Users/z5044992/Documents/python/morePVs/morePVs.py", line 2556, in runScenario
    eno.initialiseAllBatteries(scenario)
  File "C:/Users/z5044992/Documents/python/morePVs/morePVs.py", line 1380, in initialiseAllBatteries
    battery_capacity=battery_capacity_kWh)
  File "C:/Users/z5044992/Documents/python/morePVs/morePVs.py", line 429, in __init__
    sys.exit("battery-id %s is not in battery_lookup.csv :", battery_id)
TypeError: exit expected at most 1 arguments, got 2
